<?xml version="1.0"?>
<robot name="acrobot">
  <!-- Base Link -->
  <link name="base_link">
    <inertial>
      <origin xyz="0 0 0" rpy="0 0 0"/>
      <mass value="1.0"/>
      <inertia ixx="1" ixy="0" ixz="0" iyy="1" iyz="0" izz="1"/>
    </inertial>
  </link>

  <!-- Link 1 -->
  <link name="link1">
    <visual>
      <origin xyz="0.5 0 0" rpy="0 0 0"/>
      <geometry>
        <box size="1 0.1 0.1"/>
      </geometry>
      <material name="blue">
        <color rgba="0 0 1 1"/>
      </material>
    </visual>
    <collision>
      <origin xyz="0.5 0 0" rpy="0 0 0"/>
      <geometry>
        <box size="1 0.1 0.1"/>
      </geometry>
    </collision>
  </link>

  <!-- Joint 1 -->
  <joint name="joint1" type="revolute">
    <parent link="base_link"/>
    <child link="link1"/>
    <origin xyz="0 0 0" rpy="0 0 0"/>
    <axis xyz="0 0 1"/>
    <limit lower="-3.14159" upper="3.14159" effort="100" velocity="1"/>
  </joint>

  <!-- Link 2 -->
  <link name="link2">
    <visual>
      <origin xyz="0.5 0 0" rpy="0 0 0"/>
      <geometry>
        <box size="1 0.1 0.1"/>
      </geometry>
      <material name="green">
        <color rgba="0 1 0 1"/>
      </material>
    </visual>
    <collision>
      <origin xyz="0.5 0 0" rpy="0 0 0"/>
      <geometry>
        <box size="1 0.1 0.1"/>
      </geometry>
    </collision>
  </link>

  <!-- Joint 2 -->
  <joint name="joint2" type="revolute">
    <parent link="link1"/>
    <child link="link2"/>
    <origin xyz="1 0 0" rpy="0 0 0"/>
    <axis xyz="0 0 1"/>
    <limit lower="-3.14159" upper="3.14159" effort="100" velocity="1"/>
  </joint>

  <!-- End Effector -->
  <link name="end_effector">
    <visual>
      <origin xyz="0 0 0" rpy="0 0 0"/>
      <geometry>
        <sphere radius="0.05"/>
      </geometry>
      <material name="red">
        <color rgba="1 0 0 1"/>
      </material>
    </visual>
    <collision>
      <origin xyz="0.5 0 0" rpy="0 0 0"/>
      <geometry>
        <sphere radius="0.05"/>
      </geometry>
    </collision>
  </link>

  <!-- Fixed joint for the end effector -->
  <joint name="joint3" type="fixed">
    <parent link="link2"/>
    <child link="end_effector"/>
    <origin xyz="1 0 0" rpy="0 0 0"/>
  </joint>
</robot>
